[["d:\\IT\\Python\\IS_Lab_4\\test.py 29", "TypeError", "Traceback (most recent call last):\n  File \"d:\\IT\\Python\\IS_Lab_4\\test.py\", line 29, in <module>\n    raise TypeError()\nTypeError\n", "Don't push there"], ["d:\\IT\\Python\\IS_Lab_4\\test.py 34", "NameError", "Traceback (most recent call last):\n  File \"d:\\IT\\Python\\IS_Lab_4\\test.py\", line 34, in <module>\n    raise NameError()\nNameError\n", "Change your name, please"], ["d:\\IT\\Python\\IS_Lab_4\\test.py 39", "ZeroDivisionError", "Traceback (most recent call last):\n  File \"d:\\IT\\Python\\IS_Lab_4\\test.py\", line 39, in <module>\n    raise ZeroDivisionError()\nZeroDivisionError\n", "Learn mathematics"], ["d:\\IT\\Python\\IS_Lab_4\\test.py 44", "Exception: Custom", "Traceback (most recent call last):\n  File \"d:\\IT\\Python\\IS_Lab_4\\test.py\", line 44, in <module>\n    raise Exception(\"Custom\")\nException: Custom\n", "Don't use custom Exception"]]